<mujoco model="ant">
  <compiler inertiafromgeom="true" angle="degree" coordinate="local"/>
  <option timestep="0.02" integrator="RK4"/>
  <custom>
    <numeric name="init_qpos" data="0.0 0.0 0.55 1.0 0.0 0.0 0.0 0.0 1.0 0.0 -1.0 0.0 -1.0 0.0 1.0"/>
  </custom>
  <default>
    <joint limited="true" armature="1" damping="1"/>
    <geom condim="3" conaffinity="0" margin="0.01" friction="1 0.5 0.5" solref=".02 1" solimp=".8 .8 .01" rgba="0.8 0.6 0.4 1" density="5.0"/>
  </default>
  <asset>
    <texture type="skybox" builtin="gradient" width="100" height="100" rgb1="1 1 1" rgb2="0 0 0"/>
    <texture name="texgeom" type="cube" builtin="flat" mark="cross" width="127" height="1278" rgb1="0.8 0.6 0.4" rgb2="0.8 0.6 0.4" markrgb="1 1 1" random="0.01"/>
    <texture name="texplane" type="2d" builtin="checker" rgb1="0 0 0" rgb2="0.8 0.8 0.8" width="100" height="100"/>
    <material name="MatPlane" texture="texplane" shininess="1" texrepeat="60 60" specular="1" reflectance="0.5"/>
    <material name="geom" texture="texgeom" texuniform="true"/>
  </asset>
  <worldbody>
    <light directional="true" cutoff="100" exponent="1" diffuse="1 1 1" specular=".1 .1 .1" pos="0 0 1.3" dir="-0 0 -1.3"/>
    <geom name="floor" material="MatPlane" pos="0 0 0" size="40 40 40" type="plane" conaffinity="1" rgba="0.8 0.9 0.8 1" condim="3"/>
    <body name="torso" pos="0 0 0.75">
      <geom name="torso_geom" type="sphere" size="0.25" pos="0 0 0"/>
      <joint name="root" type="free" limited="false" pos="0 0 0" axis="0 0 1" margin="0.01" armature="0" damping="0"/>
      <body name="leg_0" pos="0 0 0">
        <geom fromto="0.0 0.0 0.0 0.1994 0.1994 0.0" name="aux_0_geom" size="0.08" type="capsule"/>
        <body name="aux_0" pos="0.1994 0.1994 0.0">
          <joint axis="0 0 1" name="hip_0" pos="0.0 0.0 0.0" range="-30 30" type="hinge"/>
          <geom fromto="0.0 0.0 0.0 0.1994 0.1994 0.0" name="leg_geom_0" size="0.08" type="capsule"/>
          <body pos="0.1994 0.1994 0.0">
            <joint axis="-1 1 0" name="ankle_0" pos="0.0 0.0 0.0" range="30 70" type="hinge"/>
            <geom fromto="0.0 0.0 0.0 0.3988 0.3988 0.0" name="ankle_geom_0" size="0.08" type="capsule"/>
          </body>
        </body>
      </body>
      <body name="leg_1" pos="0 0 0">
        <geom fromto="0.0 0.0 0.0 -0.1994 0.1994 0.0" name="aux_1_geom" size="0.08" type="capsule"/>
        <body name="aux_1" pos="-0.1994 0.1994 0.0">
          <joint axis="0 0 1" name="hip_1" pos="0.0 0.0 0.0" range="-30 30" type="hinge"/>
          <geom fromto="0.0 0.0 0.0 -0.1994 0.1994 0.0" name="leg_geom_1" size="0.08" type="capsule"/>
          <body pos="-0.1994 0.1994 0.0">
            <joint axis="1 1 0" name="ankle_1" pos="0.0 0.0 0.0" range="-70 -30" type="hinge"/>
            <geom fromto="0.0 0.0 0.0 -0.3988 0.3988 0.0" name="ankle_geom_1" size="0.08" type="capsule"/>
          </body>
        </body>
      </body>
      <body name="leg_2" pos="0 0 0">
        <geom fromto="0.0 0.0 0.0 -0.1994 -0.1994 0.0" name="aux_2_geom" size="0.08" type="capsule"/>
        <body name="aux_2" pos="-0.1994 -0.1994 0.0">
          <joint axis="0 0 1" name="hip_2" pos="0.0 0.0 0.0" range="-30 30" type="hinge"/>
          <geom fromto="0.0 0.0 0.0 -0.1994 -0.1994 0.0" name="leg_geom_2" size="0.08" type="capsule"/>
          <body pos="-0.1994 -0.1994 0.0">
            <joint axis="-1 1 0" name="ankle_2" pos="0.0 0.0 0.0" range="-70 -30" type="hinge"/>
            <geom fromto="0.0 0.0 0.0 -0.3988 -0.3988 0.0" name="ankle_geom_2" size="0.08" type="capsule"/>
          </body>
        </body>
      </body>
      <body name="leg_3" pos="0 0 0">
        <geom fromto="0.0 0.0 0.0 0.1994 -0.1994 0.0" name="aux_3_geom" size="0.08" type="capsule"/>
        <body name="aux_3" pos="0.1994 -0.1994 0.0">
          <joint axis="0 0 1" name="hip_3" pos="0.0 0.0 0.0" range="-30 30" type="hinge"/>
          <geom fromto="0.0 0.0 0.0 0.1994 -0.1994 0.0" name="leg_geom_3" size="0.08" type="capsule"/>
          <body pos="0.1994 -0.1994 0.0">
            <joint axis="1 1 0" name="ankle_3" pos="0.0 0.0 0.0" range="30 70" type="hinge"/>
            <geom fromto="0.0 0.0 0.0 0.3988 -0.3988 0.0" name="ankle_geom_3" size="0.08" type="capsule"/>
          </body>
        </body>
      </body>
    </body>
  </worldbody>
  <actuator>
    <motor ctrllimited="true" ctrlrange="-150.0 150.0" joint="hip_0"/>
    <motor ctrllimited="true" ctrlrange="-150.0 150.0" joint="ankle_0"/>
    <motor ctrllimited="true" ctrlrange="-150.0 150.0" joint="hip_1"/>
    <motor ctrllimited="true" ctrlrange="-150.0 150.0" joint="ankle_1"/>
    <motor ctrllimited="true" ctrlrange="-150.0 150.0" joint="hip_2"/>
    <motor ctrllimited="true" ctrlrange="-150.0 150.0" joint="ankle_2"/>
    <motor ctrllimited="true" ctrlrange="-150.0 150.0" joint="hip_3"/>
    <motor ctrllimited="true" ctrlrange="-150.0 150.0" joint="ankle_3"/>
  </actuator>
</mujoco>
